<?xml version="1.0"?>
<!--
  Robot: es165d
  Generated by: LinkForge v1.1.1
  https://github.com/arounamounchili/linkforge
  Date: 2026-01-15 08:53:01
-->
<robot name="es165_macro">
  <!-- Materials -->
  <material name="blue">
    <color rgba="0 0 1 1" />
  </material>
  <material name="black">
    <color rgba="0 0 0 1" />
  </material>
  <!-- Links -->
  <link name="world">
    <inertial>
      <mass value="1" />
      <inertia ixx="1" ixy="0" ixz="0" iyy="1" iyz="0" izz="1" />
    </inertial>
  </link>
  <link name="base_link">
    <visual>
      <origin xyz="-0.0785 -0.003773 0.109656" rpy="0 0 0" />
      <geometry>
        <mesh filename="meshes_blender/base_link_visual.stl" />
      </geometry>
      <material name="blue" />
    </visual>
    <collision>
      <geometry>
        <mesh filename="meshes_blender/base_link_collision.stl" />
      </geometry>
    </collision>
    <inertial>
      <mass value="1" />
      <inertia ixx="0.037775" ixy="-0.000017" ixz="0.00465" iyy="0.063748" iyz="-0.000015" izz="0.084785" />
    </inertial>
  </link>
  <link name="link_s">
    <visual>
      <origin xyz="0.163604 -0.081874 0.04593" rpy="0 0 0" />
      <geometry>
        <mesh filename="meshes_blender/link_s_visual.stl" />
      </geometry>
    </visual>
    <collision>
      <geometry>
        <mesh filename="meshes_blender/link_s_collision.stl" />
      </geometry>
    </collision>
    <inertial>
      <mass value="1" />
      <inertia ixx="0.079653" ixy="-0.007092" ixz="0.017974" iyy="0.137648" iyz="0.005438" izz="0.153523" />
    </inertial>
  </link>
  <link name="link_l">
    <visual>
      <origin xyz="0.3473 -0.276484 0.001696" rpy="0 0 0" />
      <geometry>
        <mesh filename="meshes_blender/link_l_visual.stl" />
      </geometry>
    </visual>
    <collision>
      <geometry>
        <mesh filename="meshes_blender/link_l_collision.stl" />
      </geometry>
    </collision>
    <inertial>
      <mass value="1" />
      <inertia ixx="0.023135" ixy="0.009622" ixz="0.00092" iyy="0.156063" iyz="0.000646" izz="0.156769" />
    </inertial>
  </link>
  <link name="link_u">
    <visual>
      <origin xyz="0.14446 -0.026313 -0.180751" rpy="0 0 0" />
      <geometry>
        <mesh filename="meshes_blender/link_u_visual.stl" />
      </geometry>
    </visual>
    <collision>
      <geometry>
        <mesh filename="meshes_blender/link_u_collision.stl" />
      </geometry>
    </collision>
    <inertial>
      <mass value="1" />
      <inertia ixx="0.093567" ixy="-0.005301" ixz="0.014698" iyy="0.089766" iyz="0.008728" izz="0.038073" />
    </inertial>
  </link>
  <link name="link_r">
    <visual>
      <origin xyz="0.004326 -0.037508 -1.187282" rpy="0 0 0" />
      <geometry>
        <mesh filename="meshes_blender/link_r_visual.stl" />
      </geometry>
    </visual>
    <collision>
      <geometry>
        <mesh filename="meshes_blender/link_r_collision.stl" />
      </geometry>
    </collision>
    <inertial>
      <mass value="1" />
      <inertia ixx="0.009081" ixy="0.000007" ixz="-0.000002" iyy="0.007906" iyz="-0.001654" izz="0.005797" />
    </inertial>
  </link>
  <link name="link_b">
    <visual>
      <origin xyz="0.000515 0.005923 -0.066019" rpy="0 0 0" />
      <geometry>
        <mesh filename="meshes_blender/link_b_visual.stl" />
      </geometry>
    </visual>
    <collision>
      <geometry>
        <mesh filename="meshes_blender/link_b_collision.stl" />
      </geometry>
    </collision>
    <inertial>
      <mass value="1" />
      <inertia ixx="0.009574" ixy="0" ixz="0" iyy="0.008842" iyz="0.00026" izz="0.005764" />
    </inertial>
  </link>
  <link name="link_t">
    <visual>
      <origin xyz="0.000266 0.000792 0.007679" rpy="0 0 0" />
      <geometry>
        <mesh filename="meshes_blender/link_t_visual.stl" />
      </geometry>
      <material name="black" />
    </visual>
    <collision>
      <geometry>
        <mesh filename="meshes_blender/link_t_collision.stl" />
      </geometry>
    </collision>
    <inertial>
      <mass value="1" />
      <inertia ixx="0.001623" ixy="0" ixz="0" iyy="0.00166" iyz="0.000003" izz="0.003176" />
    </inertial>
  </link>
  <link name="tool0">
    <inertial>
      <mass value="1" />
      <inertia ixx="1" ixy="0" ixz="0" iyy="1" iyz="0" izz="1" />
    </inertial>
  </link>
  <link name="ee_base_link">
    <visual>
      <origin xyz="0 0 0" rpy="0 0 0" />
      <geometry>
        <mesh filename="meshes_blender/ee_base_link_visual.stl" />
      </geometry>
    </visual>
    <collision>
      <origin xyz="0 0 0" rpy="0 0 0" />
      <geometry>
        <mesh filename="meshes_blender/ee_base_link_collision.stl" />
      </geometry>
    </collision>
    <inertial>
      <mass value="1" />
      <inertia ixx="0.020265" ixy="0" ixz="-0.000002" iyy="0.098548" iyz="0" izz="0.079038" />
    </inertial>
  </link>
  <link name="rw1">
    <visual>
      <origin xyz="0 0 0" rpy="0 0 0" />
      <geometry>
        <mesh filename="meshes_blender/rw1_visual.stl" />
      </geometry>
    </visual>
    <collision>
      <origin xyz="0 0 0" rpy="0 0 0" />
      <geometry>
        <mesh filename="meshes_blender/rw1_collision.stl" />
      </geometry>
    </collision>
    <inertial>
      <mass value="1" />
      <inertia ixx="0.001661" ixy="0" ixz="0.000001" iyy="0.00167" iyz="0" izz="0.002999" />
    </inertial>
  </link>
  <link name="rw2">
    <visual>
      <origin xyz="0 0 0" rpy="0 0 0" />
      <geometry>
        <mesh filename="meshes_blender/rw2_visual.stl" />
      </geometry>
    </visual>
    <collision>
      <origin xyz="0 0 0" rpy="0 0 0" />
      <geometry>
        <mesh filename="meshes_blender/rw2_collision.stl" />
      </geometry>
    </collision>
    <inertial>
      <mass value="1" />
      <inertia ixx="0.001661" ixy="0" ixz="0.000001" iyy="0.00167" iyz="0" izz="0.002999" />
    </inertial>
  </link>
  <link name="rw3">
    <visual>
      <origin xyz="0 0 0" rpy="0 0 0" />
      <geometry>
        <mesh filename="meshes_blender/rw3_visual.stl" />
      </geometry>
    </visual>
    <collision>
      <origin xyz="0 0 0" rpy="0 0 0" />
      <geometry>
        <mesh filename="meshes_blender/rw3_collision.stl" />
      </geometry>
    </collision>
    <inertial>
      <mass value="1" />
      <inertia ixx="0.001661" ixy="0" ixz="0.000001" iyy="0.00167" iyz="0" izz="0.002999" />
    </inertial>
  </link>
  <link name="rw4">
    <visual>
      <origin xyz="0 0 0" rpy="0 0 0" />
      <geometry>
        <mesh filename="meshes_blender/rw4_visual.stl" />
      </geometry>
    </visual>
    <collision>
      <origin xyz="0 0 0" rpy="0 0 0" />
      <geometry>
        <mesh filename="meshes_blender/rw4_collision.stl" />
      </geometry>
    </collision>
    <inertial>
      <mass value="1" />
      <inertia ixx="0.001661" ixy="0" ixz="0.000001" iyy="0.00167" iyz="0" izz="0.002999" />
    </inertial>
  </link>
  <!-- Joints -->
  <joint name="world_fixed_joint" type="fixed">
    <parent link="world" />
    <child link="base_link" />
  </joint>
  <joint name="joint_1_s" type="revolute">
    <origin xyz="0 0 0.45" rpy="0 0 0" />
    <parent link="base_link" />
    <child link="link_s" />
    <axis xyz="0 0 1" />
    <limit effort="0" velocity="1.570796" lower="-3.141593" upper="3.141593" />
  </joint>
  <joint name="joint_2_l" type="revolute">
    <origin xyz="0.74 0 0" rpy="0 0 0" />
    <parent link="link_s" />
    <child link="link_l" />
    <axis xyz="0 1 0" />
    <limit effort="0" velocity="1.48353" lower="-2.268928" upper="1.396263" />
  </joint>
  <joint name="joint_3_u" type="revolute">
    <origin xyz="1.15 0 0" rpy="0 0 0" />
    <parent link="link_l" />
    <child link="link_u" />
    <axis xyz="0 -1 0" />
    <limit effort="0" velocity="1.48353" lower="-1.954769" upper="3.630285" />
  </joint>
  <joint name="joint_4_r" type="revolute">
    <origin xyz="0.25 0 0" rpy="0 0 0" />
    <parent link="link_u" />
    <child link="link_r" />
    <axis xyz="0 0 1" />
    <limit effort="0" velocity="3.054326" lower="-6.283185" upper="6.283185" />
  </joint>
  <joint name="joint_5_b" type="revolute">
    <origin xyz="0 0 -1.225" rpy="0 0 0" />
    <parent link="link_r" />
    <child link="link_b" />
    <axis xyz="0 -1 0" />
    <limit effort="0" velocity="2.617994" lower="-2.268928" upper="2.268928" />
  </joint>
  <joint name="joint_6_t" type="revolute">
    <origin xyz="0 0 -0.225" rpy="0 0 0" />
    <parent link="link_b" />
    <child link="link_t" />
    <axis xyz="0 0 1" />
    <limit effort="0" velocity="4.18879" lower="-6.283185" upper="6.283185" />
  </joint>
  <joint name="joint_t_tool0" type="fixed">
    <origin xyz="0 0 0" rpy="0 -3.141593 0" />
    <parent link="link_t" />
    <child link="tool0" />
  </joint>
  <joint name="ee_base_link_joint" type="fixed">
    <origin xyz="0.004513 0 -0.0745" rpy="1.570796 0 0" />
    <parent link="link_t" />
    <child link="ee_base_link" />
  </joint>
  <joint name="rw1_joint" type="continuous">
    <origin xyz="0.000974 -0.055246 0.001299" rpy="1.570797 0 0" />
    <parent link="ee_base_link" />
    <child link="rw1" />
    <axis xyz="0 0 1" />
  </joint>
  <joint name="rw3_joint" type="continuous">
    <origin xyz="0.118956 -0.105533 0.001298" rpy="1.570796 0 -1.570796" />
    <parent link="ee_base_link" />
    <child link="rw3" />
    <axis xyz="0 0 1" />
  </joint>
  <joint name="rw2_joint" type="continuous">
    <origin xyz="-0.127511 -0.105533 0.001298" rpy="1.570796 0 1.570796" />
    <parent link="ee_base_link" />
    <child link="rw2" />
    <axis xyz="0 0 1" />
  </joint>
  <joint name="rw4_joint" type="continuous">
    <origin xyz="0.000974 -0.115515 0.131297" rpy="3.141592 0 0" />
    <parent link="ee_base_link" />
    <child link="rw4" />
    <axis xyz="0 0 1" />
  </joint>
</robot>